Traceback (most recent call last):
  File "C:\Users\deanv\anaconda3_2023\envs\jupyterbook\Lib\site-packages\jupyter_cache\executors\utils.py", line 58, in single_nb_execution
    executenb(
  File "C:\Users\deanv\anaconda3_2023\envs\jupyterbook\Lib\site-packages\nbclient\client.py", line 1305, in execute
    return NotebookClient(nb=nb, resources=resources, km=km, **kwargs).execute()
           ^^^^^^^^^^^^^^^^^^^^^^^^^^^^^^^^^^^^^^^^^^^^^^^^^^^^^^^^^^^^^^^^^^^^^
  File "C:\Users\deanv\AppData\Roaming\Python\Python311\site-packages\jupyter_core\utils\__init__.py", line 166, in wrapped
    return loop.run_until_complete(inner)
           ^^^^^^^^^^^^^^^^^^^^^^^^^^^^^^
  File "C:\Users\deanv\anaconda3_2023\envs\jupyterbook\Lib\asyncio\base_events.py", line 653, in run_until_complete
    return future.result()
           ^^^^^^^^^^^^^^^
  File "C:\Users\deanv\anaconda3_2023\envs\jupyterbook\Lib\site-packages\nbclient\client.py", line 705, in async_execute
    await self.async_execute_cell(
  File "C:\Users\deanv\anaconda3_2023\envs\jupyterbook\Lib\site-packages\nbclient\client.py", line 1058, in async_execute_cell
    await self._check_raise_for_error(cell, cell_index, exec_reply)
  File "C:\Users\deanv\anaconda3_2023\envs\jupyterbook\Lib\site-packages\nbclient\client.py", line 914, in _check_raise_for_error
    raise CellExecutionError.from_cell_and_msg(cell, exec_reply_content)
nbclient.exceptions.CellExecutionError: An error occurred while executing the following cell:
------------------
# Selecteer de gewenste kolommen
selected_columns = df_2022[['yellow cards team1', 'yellow cards team2', 'red cards team1', 'red cards team2', 'fouls against team1', 'fouls against team2', 'free kicks team1',
       'free kicks team2']]

# Bereken de som per kolom en voeg een nieuwe rij toe
sum_row = selected_columns.sum()
selected_columns = selected_columns.append(sum_row, ignore_index=True)

# Toon de bijgewerkte DataFrame
display(selected_columns)
------------------


[1;31m---------------------------------------------------------------------------[0m
[1;31mAttributeError[0m                            Traceback (most recent call last)
Cell [1;32mIn[4], line 7[0m
[0;32m      5[0m [38;5;66;03m# Bereken de som per kolom en voeg een nieuwe rij toe[39;00m
[0;32m      6[0m sum_row [38;5;241m=[39m selected_columns[38;5;241m.[39msum()
[1;32m----> 7[0m selected_columns [38;5;241m=[39m [43mselected_columns[49m[38;5;241;43m.[39;49m[43mappend[49m(sum_row, ignore_index[38;5;241m=[39m[38;5;28;01mTrue[39;00m)
[0;32m      9[0m [38;5;66;03m# Toon de bijgewerkte DataFrame[39;00m
[0;32m     10[0m display(selected_columns)

File [1;32m~\anaconda3_2023\envs\jupyterbook\Lib\site-packages\pandas\core\generic.py:5989[0m, in [0;36mNDFrame.__getattr__[1;34m(self, name)[0m
[0;32m   5982[0m [38;5;28;01mif[39;00m (
[0;32m   5983[0m     name [38;5;129;01mnot[39;00m [38;5;129;01min[39;00m [38;5;28mself[39m[38;5;241m.[39m_internal_names_set
[0;32m   5984[0m     [38;5;129;01mand[39;00m name [38;5;129;01mnot[39;00m [38;5;129;01min[39;00m [38;5;28mself[39m[38;5;241m.[39m_metadata
[0;32m   5985[0m     [38;5;129;01mand[39;00m name [38;5;129;01mnot[39;00m [38;5;129;01min[39;00m [38;5;28mself[39m[38;5;241m.[39m_accessors
[0;32m   5986[0m     [38;5;129;01mand[39;00m [38;5;28mself[39m[38;5;241m.[39m_info_axis[38;5;241m.[39m_can_hold_identifiers_and_holds_name(name)
[0;32m   5987[0m ):
[0;32m   5988[0m     [38;5;28;01mreturn[39;00m [38;5;28mself[39m[name]
[1;32m-> 5989[0m [38;5;28;01mreturn[39;00m [38;5;28;43mobject[39;49m[38;5;241;43m.[39;49m[38;5;21;43m__getattribute__[39;49m[43m([49m[38;5;28;43mself[39;49m[43m,[49m[43m [49m[43mname[49m[43m)[49m

[1;31mAttributeError[0m: 'DataFrame' object has no attribute 'append'

